c:\Users\hmets\yt-dlp>python youtube-dl https://filemoon.sx/e/jv6whayugrjc/vif.mp4 -v
python: can't open file 'c:\\Users\\hmets\\yt-dlp\\youtube-dl': [Errno 2] No such file or directory

c:\Users\hmets\yt-dlp>youtube-dl https://filemoon.sx/e/jv6whayugrjc/vif.mp4 -v
[debug] System config: []
[debug] User config: []
[debug] Custom config: []
[debug] Command-line args: ['https://filemoon.sx/e/jv6whayugrjc/vif.mp4', '-v']
[debug] Encodings: locale cp1252, fs utf-8, out utf-8, pref cp1252
[debug] youtube-dl version 2021.12.17
[debug] Python 3.12.4 (CPython AMD64 64bit) - Windows-11-10.0.22631-SP0 - OpenSSL 3.0.13 30 Jan 2024
[debug] exe versions: none
[debug] Proxy map: {}
[FileMoon] jv6whayugrjc: Downloading webpage
Traceback (most recent call last):
  File "\\?\C:\Users\hmets\AppData\Local\Programs\Python\Python312\Scripts\youtube-dl-script.py", line 33, in <module>
    sys.exit(load_entry_point('youtube-dl==2021.12.17', 'console_scripts', 'youtube-dl')())
             ^^^^^^^^^^^^^^^^^^^^^^^^^^^^^^^^^^^^^^^^^^^^^^^^^^^^^^^^^^^^^^^^^^^^^^^^^^^^^
  File "C:\Users\hmets\AppData\Local\Programs\Python\Python312\Lib\site-packages\youtube_dl-2021.12.17-py3.12.egg\youtube_dl\__init__.py", line 473, in main
    _real_main(argv)
  File "C:\Users\hmets\AppData\Local\Programs\Python\Python312\Lib\site-packages\youtube_dl-2021.12.17-py3.12.egg\youtube_dl\__init__.py", line 463, in _real_main
    retcode = ydl.download(all_urls)
              ^^^^^^^^^^^^^^^^^^^^^^
  File "C:\Users\hmets\AppData\Local\Programs\Python\Python312\Lib\site-packages\youtube_dl-2021.12.17-py3.12.egg\youtube_dl\YoutubeDL.py", line 2218, in download
    res = self.extract_info(
          ^^^^^^^^^^^^^^^^^^
  File "C:\Users\hmets\AppData\Local\Programs\Python\Python312\Lib\site-packages\youtube_dl-2021.12.17-py3.12.egg\youtube_dl\YoutubeDL.py", line 852, in extract_info
    return self.__extract_info(url, ie, download, extra_info, process)
           ^^^^^^^^^^^^^^^^^^^^^^^^^^^^^^^^^^^^^^^^^^^^^^^^^^^^^^^^^^^
  File "C:\Users\hmets\AppData\Local\Programs\Python\Python312\Lib\site-packages\youtube_dl-2021.12.17-py3.12.egg\youtube_dl\YoutubeDL.py", line 859, in wrapper
    return func(self, *args, **kwargs)
           ^^^^^^^^^^^^^^^^^^^^^^^^^^^
  File "C:\Users\hmets\AppData\Local\Programs\Python\Python312\Lib\site-packages\youtube_dl-2021.12.17-py3.12.egg\youtube_dl\YoutubeDL.py", line 955, in __extract_info
    ie_result = ie.extract(url)
                ^^^^^^^^^^^^^^^
  File "C:\Users\hmets\AppData\Local\Programs\Python\Python312\Lib\site-packages\youtube_dl-2021.12.17-py3.12.egg\youtube_dl\extractor\common.py", line 571, in extract
    ie_result = self._real_extract(url)
                ^^^^^^^^^^^^^^^^^^^^^^^
  File "C:\Users\hmets\AppData\Local\Programs\Python\Python312\Lib\site-packages\youtube_dl-2021.12.17-py3.12.egg\youtube_dl\extractor\filemoon.py", line 30, in _real_extract
    packed = matches[-1]
             ~~~~~~~^^^^
IndexError: list index out of range
